Workbook

Sheet Raw_Data
A1: country | B1: country_code_x | C1: region | D1: income_level | E1: capital_city | F1: latitude | G1: longitude | H1: country_code_y | I1: inflation_year | J1: inflation_annual_pct | K1: cost_living_index | L1: rent_index | M1: groceries_index | N1: restaurants_index | O1: purchasing_power_index | P1: bread_price_usd | Q1: transport_oneway_usd | R1: transport_monthly_pass_usd | S1: rent_monthly_usd | T1: utilities_monthly_usd
A2: Aruba | C2: Latin America & Caribbean | D2: High income | E2: Oranjestad | F2: 12.5167 | G2: -70.0167
A3: Afghanistan | C3: Middle East, North Africa, Afghanistan & Pakistan | D3: Low income | E3: Kabul | F3: 34.5228 | G3: 69.1761 | H3: AFG | I3: 2024 | J3: -6.6011856 | K3: 38.2 | L3: 8.2 | M3: 36.8 | N3: 36.9 | O3: 48.5 | P3: 0.88 | Q3: 1.05 | R3: 12.8 | S3: 85 | T3: 20
A4: Angola | C4: Sub-Saharan Africa | D4: Lower middle income | E4: Luanda | F4: -8.81155 | G4: 13.242 | H4: AGO | I4: 2024 | J4: 28.240495
A5: Albania | C5: Europe & Central Asia | D5: Upper middle income | E5: Tirane | F5: 41.3317 | G5: 19.8172 | H5: ALB | I5: 2024 | J5: 2.2158738
A6: Andorra | C6: Europe & Central Asia | D6: High income | E6: Andorra la Vella | F6: 42.5075 | G6: 1.5218
A7: United Arab Emirates | C7: Middle East, North Africa, Afghanistan & Pakistan | D7: High income | E7: Abu Dhabi | F7: 24.4764 | G7: 54.3705 | H7: ARE | I7: 2024 | J7: 1.6633651 | K7: 72.4 | L7: 34.2 | M7: 68.5 | N7: 70.8 | O7: 96.2 | S7: 1100
A8: Argentina | C8: Latin America & Caribbean | D8: Upper middle income | E8: Buenos Aires | F8: -34.6118 | G8: -58.4173 | H8: ARG | I8: 2024 | J8: 219.88393
A9: Armenia | C9: Europe & Central Asia | D9: Upper middle income | E9: Yerevan | F9: 40.1596 | G9: 44.509 | H9: ARM | I9: 2024 | J9: 0.26951198
A10: American Samoa | C10: East Asia & Pacific | D10: High income | E10: Pago Pago | F10: -14.2846 | G10: -170.691
A11: Antigua and Barbuda | C11: Latin America & Caribbean | D11: High income | E11: Saint John's | F11: 17.1175 | G11: -61.8456 | H11: ATG | I11: 2024 | J11: 6.198867
A12: Australia | C12: East Asia & Pacific | D12: High income | E12: Canberra | F12: -35.282 | G12: 149.129 | H12: AUS | I12: 2024 | J12: 3.1665667 | K12: 69.5 | L12: 32.8 | M12: 65.4 | N12: 68.9 | O12: 95.6 | P12: 3.25 | S12: 1450 | T12: 140
A13: Austria | C13: Europe & Central Asia | D13: High income | E13: Vienna | F13: 48.2201 | G13: 16.3798 | H13: AUT | I13: 2024 | J13: 2.9379157
A14: Azerbaijan | C14: Europe & Central Asia | D14: Upper middle income | E14: Baku | F14: 40.3834 | G14: 49.8932 | H14: AZE | I14: 2024 | J14: 2.2121719 | P14: 0.46
A15: Burundi | C15: Sub-Saharan Africa | D15: Low income | E15: Bujumbura | F15: -3.3784 | G15: 29.3639 | H15: BDI | I15: 2024 | J15: 20.212493
A16: Belgium | C16: Europe & Central Asia | D16: High income | E16: Brussels | F16: 50.8371 | G16: 4.36761 | H16: BEL | I16: 2024 | J16: 3.1434914
A17: Benin | C17: Sub-Saharan Africa | D17: Lower middle income | E17: Porto-Novo | F17: 6.4779 | G17: 2.6323 | H17: BEN | I17: 2024 | J17: 1.1609309
A18: Burkina Faso | C18: Sub-Saharan Africa | D18: Low income | E18: Ouagadougou | F18: 12.3605 | G18: -1.53395 | H18: BFA | I18: 2024 | J18: 4.1908172
A19: Bangladesh | C19: South Asia | D19: Lower middle income | E19: Dhaka | F19: 23.7055 | G19: 90.4113 | H19: BGD | I19: 2024 | J19: 10.465748 | K19: 39.5 | L19: 8.8 | M19: 38.1 | N19: 38.2 | O19: 50.8 | P19: 0.95 | Q19: 1.18 | R19: 14.5 | S19: 100 | T19: 25
A20: Bulgaria | C20: Europe & Central Asia | D20: High income | E20: Sofia | F20: 42.7105 | G20: 23.3238 | H20: BGR | I20: 2024 | J20: 2.4465194
A21: Bahrain | C21: Middle East, North Africa, Afghanistan & Pakistan | D21: High income | E21: Manama | F21: 26.1921 | G21: 50.5354 | H21: BHR | I21: 2024 | J21: 0.91963546 | K21: 65.2 | L21: 26.1 | M21: 61.8 | N21: 63.5 | O21: 86.2 | S21: 600
A22: Bahamas, The | C22: Latin America & Caribbean | D22: High income | E22: Nassau | F22: 25.0661 | G22: -77.339 | H22: BHS | I22: 2024 | J22: 0.40916249
A23: Bosnia and Herzegovina | C23: Europe & Central Asia | D23: Upper middle income | E23: Sarajevo | F23: 43.8607 | G23: 18.4214 | H23: BIH | I23: 2023 | J23: 6.1059011
A24: Belarus | C24: Europe & Central Asia | D24: Upper middle income | E24: Minsk | F24: 53.9678 | G24: 27.5766 | H24: BLR | I24: 2024 | J24: 5.7853191
A25: Belize | C25: Latin America & Caribbean | D25: Upper middle income | E25: Belmopan | F25: 17.2534 | G25: -88.7713 | H25: BLZ | I25: 2024 | J25: 3.2895599
A26: Bermuda | C26: North America | D26: High income | E26: Hamilton | F26: 32.3293 | G26: -64.706 | P26: 8.61
A27: Bolivia | C27: Latin America & Caribbean | D27: Lower middle income | E27: La Paz | F27: -13.9908 | G27: -66.1936 | H27: BOL | I27: 2024 | J27: 5.0997657
A28: Brazil | C28: Latin America & Caribbean | D28: Upper middle income | E28: Brasilia | F28: -15.7801 | G28: -47.9292 | H28: BRA | I28: 2024 | J28: 4.3674641 | K28: 51.4 | L28: 15.9 | M28: 49.2 | N28: 50.1 | O28: 67.5 | P28: 1.85 | Q28: 2.85 | R28: 52.4 | S28: 270 | T28: 70
A29: Barbados | C29: Latin America & Caribbean | D29: High income | E29: Bridgetown | F29: 13.0935 | G29: -59.6105 | H29: BRB | I29: 2024 | J29: 1.4464366 | K29: 75.2 | L29: 41.8 | M29: 70.8 | N29: 73.2 | O29: 88.5 | S29: 1200
A30: Brunei Darussalam | C30: East Asia & Pacific | D30: High income | E30: Bandar Seri Begawan | F30: 4.94199 | G30: 114.946 | H30: BRN | I30: 2024 | J30: -0.38867417
A31: Bhutan | C31: South Asia | D31: Lower middle income | E31: Thimphu | F31: 27.5768 | G31: 89.6177 | H31: BTN | I31: 2024 | J31: 2.7613157
A32: Botswana | C32: Sub-Saharan Africa | D32: Upper middle income | E32: Gaborone | F32: -24.6544 | G32: 25.9201 | H32: BWA | I32: 2024 | J32: 2.8183513
A33: Central African Republic | C33: Sub-Saharan Africa | D33: Low income | E33: Bangui | F33: 5.63056 | G33: 21.6407 | H33: CAF | I33: 2024 | J33: 1.477336
A34: Canada | C34: North America | D34: High income | E34: Ottawa | F34: 45.4215 | G34: -75.6919 | H34: CAN | I34: 2024 | J34: 2.3815838 | K34: 65.4 | L34: 28.4 | M34: 61.5 | N34: 64.2 | O34: 92.1 | P34: 3.18 | S34: 1200 | T34: 145
A35: Switzerland | C35: Europe & Central Asia | D35: High income | E35: Bern | F35: 46.948 | G35: 7.44821 | H35: CHE | I35: 2024 | J35: 1.0623404 | K35: 82.3 | L35: 50.1 | M35: 75.2 | N35: 88.4 | O35: 120.5 | P35: 3.81 | Q35: 6.36 | R35: 149.7 | S35: 1850 | T35: 220
A36: Channel Islands | C36: Europe & Central Asia | D36: High income
A37: Chile | C37: Latin America & Caribbean | D37: High income | E37: Santiago | F37: -33.475 | G37: -70.6475 | H37: CHL | I37: 2024 | J37: 4.2976389
A38: China | C38: East Asia & Pacific | D38: Upper middle income | E38: Beijing | F38: 40.0495 | G38: 116.286 | H38: CHN | I38: 2024 | J38: 0.21812894 | K38: 49.8 | L38: 14.8 | M38: 47.8 | N38: 48.5 | O38: 64.2 | P38: 1.65 | Q38: 2.45 | R38: 42.8 | S38: 540 | T38: 80
A39: Cote d'Ivoire | C39: Sub-Saharan Africa | D39: Lower middle income | E39: Yamoussoukro | F39: 5.332 | G39: -4.0305 | H39: CIV | I39: 2024 | J39: 3.4505303
A40: Cameroon | C40: Sub-Saharan Africa | D40: Lower middle income | E40: Yaounde | F40: 3.8721 | G40: 11.5174 | H40: CMR | I40: 2024 | J40: 4.5333135
...

Sheet Clean_Data
A1: country | B1: region | C1: income_level | D1: capital_city | E1: latitude | F1: longitude | G1: inflation_year | H1: inflation_annual_pct | I1: cost_living_index | J1: rent_index | K1: groceries_index | L1: restaurants_index | M1: purchasing_power_index | N1: bread_price_usd | O1: transport_oneway_usd | P1: transport_monthly_pass_usd | Q1: rent_monthly_usd | R1: utilities_monthly_usd | S1: data_completeness | T1: expansion_affordability_score | U1: rank_key
A2: Afghanistan | B2: Middle East, North Africa, Afghanistan & Pakistan | C2: Low income | D2: Kabul | E2: 34.5228 | F2: 69.1761 | G2: 2024 | H2: -6.6 | I2: 38.2 | J2: 8.2 | K2: 36.8 | L2: 36.9 | M2: 48.5 | N2: 0.88 | O2: 1.05 | P2: 12.8 | Q2: 85 | R2: 20 | S2: Full data | T2: 69.4 | U2: =T2+(ROW()-2)*0.0000001 -> 69.4
A3: Albania | B3: Europe & Central Asia | C3: Upper middle income | D3: Tirane | E3: 41.3317 | F3: 19.8172 | G3: 2024 | H3: 2.22 | S3: Inflation only | T3: 56.8 | U3: =T3+(ROW()-2)*0.0000001 -> 56.8
A4: Algeria | B4: Middle East, North Africa, Afghanistan & Pakistan | C4: Upper middle income | D4: Algiers | E4: 36.7397 | F4: 3.05097 | G4: 2024 | H4: 4.05 | S4: Inflation only | T4: 56.3 | U4: =T4+(ROW()-2)*0.0000001 -> 56.3
A5: American Samoa | B5: East Asia & Pacific | C5: High income | D5: Pago Pago | E5: -14.2846 | F5: -170.691 | S5: Reference only | T5: 54.5 | U5: =T5+(ROW()-2)*0.0000001 -> 54.5
A6: Andorra | B6: Europe & Central Asia | C6: High income | D6: Andorra la Vella | E6: 42.5075 | F6: 1.5218 | S6: Reference only | T6: 54.5 | U6: =T6+(ROW()-2)*0.0000001 -> 54.5
A7: Angola | B7: Sub-Saharan Africa | C7: Lower middle income | D7: Luanda | E7: -8.81155 | F7: 13.242 | G7: 2024 | H7: 28.24 | S7: Inflation only | T7: 49 | U7: =T7+(ROW()-2)*0.0000001 -> 49
A8: Antigua and Barbuda | B8: Latin America & Caribbean | C8: High income | D8: Saint John's | E8: 17.1175 | F8: -61.8456 | G8: 2024 | H8: 6.2 | S8: Inflation only | T8: 55.6 | U8: =T8+(ROW()-2)*0.0000001 -> 55.600001
A9: Argentina | B9: Latin America & Caribbean | C9: Upper middle income | D9: Buenos Aires | E9: -34.6118 | F9: -58.4173 | G9: 2024 | H9: 219.88 | S9: Inflation only | T9: 42.5 | U9: =T9+(ROW()-2)*0.0000001 -> 42.500001
A10: Armenia | B10: Europe & Central Asia | C10: Upper middle income | D10: Yerevan | E10: 40.1596 | F10: 44.509 | G10: 2024 | H10: 0.27 | S10: Inflation only | T10: 57.4 | U10: =T10+(ROW()-2)*0.0000001 -> 57.400001
A11: Aruba | B11: Latin America & Caribbean | C11: High income | D11: Oranjestad | E11: 12.5167 | F11: -70.0167 | S11: Reference only | T11: 54.5 | U11: =T11+(ROW()-2)*0.0000001 -> 54.500001
A12: Australia | B12: East Asia & Pacific | C12: High income | D12: Canberra | E12: -35.282 | F12: 149.129 | G12: 2024 | H12: 3.17 | I12: 69.5 | J12: 32.8 | K12: 65.4 | L12: 68.9 | M12: 95.6 | N12: 3.25 | Q12: 1450 | R12: 140 | S12: Full data | T12: 68.3 | U12: =T12+(ROW()-2)*0.0000001 -> 68.300001
A13: Austria | B13: Europe & Central Asia | C13: High income | D13: Vienna | E13: 48.2201 | F13: 16.3798 | G13: 2024 | H13: 2.94 | S13: Inflation only | T13: 56.6 | U13: =T13+(ROW()-2)*0.0000001 -> 56.600001
A14: Azerbaijan | B14: Europe & Central Asia | C14: Upper middle income | D14: Baku | E14: 40.3834 | F14: 49.8932 | G14: 2024 | H14: 2.21 | S14: Inflation only | T14: 56.8 | U14: =T14+(ROW()-2)*0.0000001 -> 56.800001
A15: Bahamas, The | B15: Latin America & Caribbean | C15: High income | D15: Nassau | E15: 25.0661 | F15: -77.339 | G15: 2024 | H15: 0.41 | S15: Inflation only | T15: 57.4 | U15: =T15+(ROW()-2)*0.0000001 -> 57.400001
A16: Bahrain | B16: Middle East, North Africa, Afghanistan & Pakistan | C16: High income | D16: Manama | E16: 26.1921 | F16: 50.5354 | G16: 2024 | H16: 0.92 | I16: 65.2 | J16: 26.1 | K16: 61.8 | L16: 63.5 | M16: 86.2 | Q16: 600 | S16: Full data | T16: 68.2 | U16: =T16+(ROW()-2)*0.0000001 -> 68.200001
A17: Bangladesh | B17: South Asia | C17: Lower middle income | D17: Dhaka | E17: 23.7055 | F17: 90.4113 | G17: 2024 | H17: 10.47 | I17: 39.5 | J17: 8.8 | K17: 38.1 | L17: 38.2 | M17: 50.8 | N17: 0.95 | O17: 1.18 | P17: 14.5 | Q17: 100 | R17: 25 | S17: Full data | T17: 64.5 | U17: =T17+(ROW()-2)*0.0000001 -> 64.500001
A18: Barbados | B18: Latin America & Caribbean | C18: High income | D18: Bridgetown | E18: 13.0935 | F18: -59.6105 | G18: 2024 | H18: 1.45 | I18: 75.2 | J18: 41.8 | K18: 70.8 | L18: 73.2 | M18: 88.5 | Q18: 1200 | S18: Full data | T18: 62.9 | U18: =T18+(ROW()-2)*0.0000001 -> 62.900002
A19: Belarus | B19: Europe & Central Asia | C19: Upper middle income | D19: Minsk | E19: 53.9678 | F19: 27.5766 | G19: 2024 | H19: 5.79 | S19: Inflation only | T19: 55.8 | U19: =T19+(ROW()-2)*0.0000001 -> 55.800002
A20: Belgium | B20: Europe & Central Asia | C20: High income | D20: Brussels | E20: 50.8371 | F20: 4.36761 | G20: 2024 | H20: 3.14 | S20: Inflation only | T20: 56.6 | U20: =T20+(ROW()-2)*0.0000001 -> 56.600002
A21: Belize | B21: Latin America & Caribbean | C21: Upper middle income | D21: Belmopan | E21: 17.2534 | F21: -88.7713 | G21: 2024 | H21: 3.29 | S21: Inflation only | T21: 56.5 | U21: =T21+(ROW()-2)*0.0000001 -> 56.500002
A22: Benin | B22: Sub-Saharan Africa | C22: Lower middle income | D22: Porto-Novo | E22: 6.4779 | F22: 2.6323 | G22: 2024 | H22: 1.16 | S22: Inflation only | T22: 57.2 | U22: =T22+(ROW()-2)*0.0000001 -> 57.200002
A23: Bermuda | B23: North America | C23: High income | D23: Hamilton | E23: 32.3293 | F23: -64.706 | S23: Reference only | T23: 54.5 | U23: =T23+(ROW()-2)*0.0000001 -> 54.500002
A24: Bhutan | B24: South Asia | C24: Lower middle income | D24: Thimphu | E24: 27.5768 | F24: 89.6177 | G24: 2024 | H24: 2.76 | S24: Inflation only | T24: 56.7 | U24: =T24+(ROW()-2)*0.0000001 -> 56.700002
A25: Bolivia | B25: Latin America & Caribbean | C25: Lower middle income | D25: La Paz | E25: -13.9908 | F25: -66.1936 | G25: 2024 | H25: 5.1 | S25: Inflation only | T25: 56 | U25: =T25+(ROW()-2)*0.0000001 -> 56.000002
A26: Bosnia and Herzegovina | B26: Europe & Central Asia | C26: Upper middle income | D26: Sarajevo | E26: 43.8607 | F26: 18.4214 | G26: 2023 | H26: 6.11 | S26: Inflation only | T26: 55.7 | U26: =T26+(ROW()-2)*0.0000001 -> 55.700002
A27: Botswana | B27: Sub-Saharan Africa | C27: Upper middle income | D27: Gaborone | E27: -24.6544 | F27: 25.9201 | G27: 2024 | H27: 2.82 | S27: Inflation only | T27: 56.7 | U27: =T27+(ROW()-2)*0.0000001 -> 56.700002
A28: Brazil | B28: Latin America & Caribbean | C28: Upper middle income | D28: Brasilia | E28: -15.7801 | F28: -47.9292 | G28: 2024 | H28: 4.37 | I28: 51.4 | J28: 15.9 | K28: 49.2 | L28: 50.1 | M28: 67.5 | N28: 1.85 | O28: 2.85 | P28: 52.4 | Q28: 270 | R28: 70 | S28: Full data | T28: 66.9 | U28: =T28+(ROW()-2)*0.0000001 -> 66.900003
A29: British Virgin Islands | B29: Latin America & Caribbean | C29: High income | D29: Road Town | E29: 18.431389 | F29: -64.623056 | S29: Reference only | T29: 54.5 | U29: =T29+(ROW()-2)*0.0000001 -> 54.500003
A30: Brunei Darussalam | B30: East Asia & Pacific | C30: High income | D30: Bandar Seri Begawan | E30: 4.94199 | F30: 114.946 | G30: 2024 | H30: -0.39 | S30: Inflation only | T30: 57.6 | U30: =T30+(ROW()-2)*0.0000001 -> 57.600003
A31: Bulgaria | B31: Europe & Central Asia | C31: High income | D31: Sofia | E31: 42.7105 | F31: 23.3238 | G31: 2024 | H31: 2.45 | S31: Inflation only | T31: 56.8 | U31: =T31+(ROW()-2)*0.0000001 -> 56.800003
A32: Burkina Faso | B32: Sub-Saharan Africa | C32: Low income | D32: Ouagadougou | E32: 12.3605 | F32: -1.53395 | G32: 2024 | H32: 4.19 | S32: Inflation only | T32: 56.2 | U32: =T32+(ROW()-2)*0.0000001 -> 56.200003
A33: Burundi | B33: Sub-Saharan Africa | C33: Low income | D33: Bujumbura | E33: -3.3784 | F33: 29.3639 | G33: 2024 | H33: 20.21 | S33: Inflation only | T33: 51.4 | U33: =T33+(ROW()-2)*0.0000001 -> 51.400003
A34: Cabo Verde | B34: Sub-Saharan Africa | C34: Upper middle income | D34: Praia | E34: 14.9218 | F34: -23.5087 | G34: 2024 | H34: 1.05 | S34: Inflation only | T34: 57.2 | U34: =T34+(ROW()-2)*0.0000001 -> 57.200003
A35: Cambodia | B35: East Asia & Pacific | C35: Lower middle income | D35: Phnom Penh | E35: 11.5556 | F35: 104.874 | G35: 2024 | H35: 0.81 | I35: 50.2 | J35: 14.5 | K35: 48.2 | L35: 48.5 | M35: 65.2 | Q35: 160 | S35: Full data | T35: 67.8 | U35: =T35+(ROW()-2)*0.0000001 -> 67.800003
A36: Cameroon | B36: Sub-Saharan Africa | C36: Lower middle income | D36: Yaounde | E36: 3.8721 | F36: 11.5174 | G36: 2024 | H36: 4.53 | S36: Inflation only | T36: 56.1 | U36: =T36+(ROW()-2)*0.0000001 -> 56.100003
A37: Canada | B37: North America | C37: High income | D37: Ottawa | E37: 45.4215 | F37: -75.6919 | G37: 2024 | H37: 2.38 | I37: 65.4 | J37: 28.4 | K37: 61.5 | L37: 64.2 | M37: 92.1 | N37: 3.18 | Q37: 1200 | R37: 145 | S37: Full data | T37: 69.4 | U37: =T37+(ROW()-2)*0.0000001 -> 69.400003
A38: Cayman Islands | B38: Latin America & Caribbean | C38: High income | D38: George Town | E38: 19.3022 | F38: -81.3857 | I38: 94.3 | J38: 60.2 | K38: 85.6 | L38: 92.1 | M38: 115.8 | N38: 6.36 | Q38: 2500 | S38: Cost data only | T38: 60.5 | U38: =T38+(ROW()-2)*0.0000001 -> 60.500004
A39: Central African Republic | B39: Sub-Saharan Africa | C39: Low income | D39: Bangui | E39: 5.63056 | F39: 21.6407 | G39: 2024 | H39: 1.48 | S39: Inflation only | T39: 57.1 | U39: =T39+(ROW()-2)*0.0000001 -> 57.100004
A40: Chad | B40: Sub-Saharan Africa | C40: Low income | D40: N'Djamena | E40: 12.1048 | F40: 15.0445 | G40: 2024 | H40: 8.9 | S40: Inflation only | T40: 54.8 | U40: =T40+(ROW()-2)*0.0000001 -> 54.800004
...

Sheet Regional_Summary
A1: Regional Cost-of-Living Summary
A2: All figures computed live via AVERAGEIFS/COUNTIFS against Clean_Data
A4: Region | B4: Countries Reporting Cost Data | C4: Avg Cost of Living Index | D4: Avg Rent (USD/mo) | E4: Avg Purchasing Power Index | F4: Avg Inflation %
A5: East Asia & Pacific | B5: =COUNTIFS(Clean_Data!B2:B218,A5,Clean_Data!I2:I218,"<>") -> 12 | C5: =IFERROR(ROUND(AVERAGEIFS(Clean_Data!I2:I218,Clean_Data!B2:B218,A5),1),"n/a") -> 56.8 | D5: =IFERROR(ROUND(AVERAGEIFS(Clean_Data!Q2:Q218,Clean_Data!B2:B218,A5),0),"n/a") -> 752 | E5: =IFERROR(ROUND(AVERAGEIFS(Clean_Data!M2:M218,Clean_Data!B2:B218,A5),1),"n/a") -> 73.8 | F5: =IFERROR(ROUND(AVERAGEIFS(Clean_Data!H2:H218,Clean_Data!B2:B218,A5),2),"n/a") -> 3.13
A6: Europe & Central Asia | B6: =COUNTIFS(Clean_Data!B2:B218,A6,Clean_Data!I2:I218,"<>") -> 13 | C6: =IFERROR(ROUND(AVERAGEIFS(Clean_Data!I2:I218,Clean_Data!B2:B218,A6),1),"n/a") -> 66.6 | D6: =IFERROR(ROUND(AVERAGEIFS(Clean_Data!Q2:Q218,Clean_Data!B2:B218,A6),0),"n/a") -> 773 | E6: =IFERROR(ROUND(AVERAGEIFS(Clean_Data!M2:M218,Clean_Data!B2:B218,A6),1),"n/a") -> 91.2 | F6: =IFERROR(ROUND(AVERAGEIFS(Clean_Data!H2:H218,Clean_Data!B2:B218,A6),2),"n/a") -> 4.43
A7: Latin America & Caribbean | B7: =COUNTIFS(Clean_Data!B2:B218,A7,Clean_Data!I2:I218,"<>") -> 4 | C7: =IFERROR(ROUND(AVERAGEIFS(Clean_Data!I2:I218,Clean_Data!B2:B218,A7),1),"n/a") -> 68.4 | D7: =IFERROR(ROUND(AVERAGEIFS(Clean_Data!Q2:Q218,Clean_Data!B2:B218,A7),0),"n/a") -> 1080 | E7: =IFERROR(ROUND(AVERAGEIFS(Clean_Data!M2:M218,Clean_Data!B2:B218,A7),1),"n/a") -> 85.4 | F7: =IFERROR(ROUND(AVERAGEIFS(Clean_Data!H2:H218,Clean_Data!B2:B218,A7),2),"n/a") -> 11.21
A8: Middle East, North Africa, Afghanistan & Pakistan | B8: =COUNTIFS(Clean_Data!B2:B218,A8,Clean_Data!I2:I218,"<>") -> 8 | C8: =IFERROR(ROUND(AVERAGEIFS(Clean_Data!I2:I218,Clean_Data!B2:B218,A8),1),"n/a") -> 61.3 | D8: =IFERROR(ROUND(AVERAGEIFS(Clean_Data!Q2:Q218,Clean_Data!B2:B218,A8),0),"n/a") -> 598 | E8: =IFERROR(ROUND(AVERAGEIFS(Clean_Data!M2:M218,Clean_Data!B2:B218,A8),1),"n/a") -> 80.3 | F8: =IFERROR(ROUND(AVERAGEIFS(Clean_Data!H2:H218,Clean_Data!B2:B218,A8),2),"n/a") -> 9.53
A9: North America | B9: =COUNTIFS(Clean_Data!B2:B218,A9,Clean_Data!I2:I218,"<>") -> 2 | C9: =IFERROR(ROUND(AVERAGEIFS(Clean_Data!I2:I218,Clean_Data!B2:B218,A9),1),"n/a") -> 69.9 | D9: =IFERROR(ROUND(AVERAGEIFS(Clean_Data!Q2:Q218,Clean_Data!B2:B218,A9),0),"n/a") -> 1402 | E9: =IFERROR(ROUND(AVERAGEIFS(Clean_Data!M2:M218,Clean_Data!B2:B218,A9),1),"n/a") -> 96.1 | F9: =IFERROR(ROUND(AVERAGEIFS(Clean_Data!H2:H218,Clean_Data!B2:B218,A9),2),"n/a") -> 2.67
A10: South Asia | B10: =COUNTIFS(Clean_Data!B2:B218,A10,Clean_Data!I2:I218,"<>") -> 4 | C10: =IFERROR(ROUND(AVERAGEIFS(Clean_Data!I2:I218,Clean_Data!B2:B218,A10),1),"n/a") -> 48.3 | D10: =IFERROR(ROUND(AVERAGEIFS(Clean_Data!Q2:Q218,Clean_Data!B2:B218,A10),0),"n/a") -> 154 | E10: =IFERROR(ROUND(AVERAGEIFS(Clean_Data!M2:M218,Clean_Data!B2:B218,A10),1),"n/a") -> 62.8 | F10: =IFERROR(ROUND(AVERAGEIFS(Clean_Data!H2:H218,Clean_Data!B2:B218,A10),2),"n/a") -> 3.98
A11: Sub-Saharan Africa | B11: =COUNTIFS(Clean_Data!B2:B218,A11,Clean_Data!I2:I218,"<>") -> 2 | C11: =IFERROR(ROUND(AVERAGEIFS(Clean_Data!I2:I218,Clean_Data!B2:B218,A11),1),"n/a") -> 45.5 | D11: =IFERROR(ROUND(AVERAGEIFS(Clean_Data!Q2:Q218,Clean_Data!B2:B218,A11),0),"n/a") -> 250 | E11: =IFERROR(ROUND(AVERAGEIFS(Clean_Data!M2:M218,Clean_Data!B2:B218,A11),1),"n/a") -> 59.2 | F11: =IFERROR(ROUND(AVERAGEIFS(Clean_Data!H2:H218,Clean_Data!B2:B218,A11),2),"n/a") -> 15.54

Sheet Dashboard
B2: Global Market Expansion & Cost-of-Living Intelligence
B3: Source: Kaggle — World Bank inflation data + cost-of-living index mashup (217 countries)
B6: Total Countries (Reference) | D6: =COUNTA(Clean_Data!A2:A218) -> 217
B7: Countries with Full Cost Data | D7: =COUNTIF(Clean_Data!S2:S218,"Full data") -> 43
B8: Countries with Inflation Data Only | D8: =COUNTIF(Clean_Data!S2:S218,"Inflation only") -> 136
B9: Highest Inflation (Risk Flag) | D9: =INDEX(Clean_Data!A2:A218,MATCH(MAX(Clean_Data!H2:H218),Clean_Data!H2:H218,0)) -> Argentina
B10: Most Affordable (Full Data, by Score) | D10: =INDEX(Clean_Data!A2:A218,MATCH(MAX(Clean_Data!T2:T218),Clean_Data!T2:T218,0)) -> Switzerland
B13: Top 10 Countries — Expansion Affordability Score (Full Data Only)
B14: Rank | C14: Country | D14: Region | E14: Score
B15: 1 | C15: =INDEX(Clean_Data!A$2:A$218,MATCH(F15,Clean_Data!U$2:U$218,0)) -> Switzerland | D15: =INDEX(Clean_Data!B$2:B$218,MATCH(F15,Clean_Data!U$2:U$218,0)) -> Europe & Central Asia | E15: =INDEX(Clean_Data!T$2:T$218,MATCH(F15,Clean_Data!U$2:U$218,0)) -> 70.5 | F15: =LARGE(Clean_Data!U$2:U$218,B15) -> 70.500019
B16: 2 | C16: =INDEX(Clean_Data!A$2:A$218,MATCH(F16,Clean_Data!U$2:U$218,0)) -> Germany | D16: =INDEX(Clean_Data!B$2:B$218,MATCH(F16,Clean_Data!U$2:U$218,0)) -> Europe & Central Asia | E16: =INDEX(Clean_Data!T$2:T$218,MATCH(F16,Clean_Data!U$2:U$218,0)) -> 69.9 | F16: =LARGE(Clean_Data!U$2:U$218,B16) -> 69.900007
B17: 3 | C17: =INDEX(Clean_Data!A$2:A$218,MATCH(F17,Clean_Data!U$2:U$218,0)) -> Denmark | D17: =INDEX(Clean_Data!B$2:B$218,MATCH(F17,Clean_Data!U$2:U$218,0)) -> Europe & Central Asia | E17: =INDEX(Clean_Data!T$2:T$218,MATCH(F17,Clean_Data!U$2:U$218,0)) -> 69.9 | F17: =LARGE(Clean_Data!U$2:U$218,B17) -> 69.900005
B18: 4 | C18: =INDEX(Clean_Data!A$2:A$218,MATCH(F18,Clean_Data!U$2:U$218,0)) -> Canada | D18: =INDEX(Clean_Data!B$2:B$218,MATCH(F18,Clean_Data!U$2:U$218,0)) -> North America | E18: =INDEX(Clean_Data!T$2:T$218,MATCH(F18,Clean_Data!U$2:U$218,0)) -> 69.4 | F18: =LARGE(Clean_Data!U$2:U$218,B18) -> 69.400003
B19: 5 | C19: =INDEX(Clean_Data!A$2:A$218,MATCH(F19,Clean_Data!U$2:U$218,0)) -> Afghanistan | D19: =INDEX(Clean_Data!B$2:B$218,MATCH(F19,Clean_Data!U$2:U$218,0)) -> Middle East, North Africa, Afghanistan & Pakistan | E19: =INDEX(Clean_Data!T$2:T$218,MATCH(F19,Clean_Data!U$2:U$218,0)) -> 69.4 | F19: =LARGE(Clean_Data!U$2:U$218,B19) -> 69.4
B20: 6 | C20: =INDEX(Clean_Data!A$2:A$218,MATCH(F20,Clean_Data!U$2:U$218,0)) -> Norway | D20: =INDEX(Clean_Data!B$2:B$218,MATCH(F20,Clean_Data!U$2:U$218,0)) -> Europe & Central Asia | E20: =INDEX(Clean_Data!T$2:T$218,MATCH(F20,Clean_Data!U$2:U$218,0)) -> 69.2 | F20: =LARGE(Clean_Data!U$2:U$218,B20) -> 69.200015
B21: 7 | C21: =INDEX(Clean_Data!A$2:A$218,MATCH(F21,Clean_Data!U$2:U$218,0)) -> France | D21: =INDEX(Clean_Data!B$2:B$218,MATCH(F21,Clean_Data!U$2:U$218,0)) -> Europe & Central Asia | E21: =INDEX(Clean_Data!T$2:T$218,MATCH(F21,Clean_Data!U$2:U$218,0)) -> 68.9 | F21: =LARGE(Clean_Data!U$2:U$218,B21) -> 68.900007
B22: 8 | C22: =INDEX(Clean_Data!A$2:A$218,MATCH(F22,Clean_Data!U$2:U$218,0)) -> Italy | D22: =INDEX(Clean_Data!B$2:B$218,MATCH(F22,Clean_Data!U$2:U$218,0)) -> Europe & Central Asia | E22: =INDEX(Clean_Data!T$2:T$218,MATCH(F22,Clean_Data!U$2:U$218,0)) -> 68.5 | F22: =LARGE(Clean_Data!U$2:U$218,B22) -> 68.50001
B23: 9 | C23: =INDEX(Clean_Data!A$2:A$218,MATCH(F23,Clean_Data!U$2:U$218,0)) -> Portugal | D23: =INDEX(Clean_Data!B$2:B$218,MATCH(F23,Clean_Data!U$2:U$218,0)) -> Europe & Central Asia | E23: =INDEX(Clean_Data!T$2:T$218,MATCH(F23,Clean_Data!U$2:U$218,0)) -> 68.4 | F23: =LARGE(Clean_Data!U$2:U$218,B23) -> 68.400016
B24: 10 | C24: =INDEX(Clean_Data!A$2:A$218,MATCH(F24,Clean_Data!U$2:U$218,0)) -> Thailand | D24: =INDEX(Clean_Data!B$2:B$218,MATCH(F24,Clean_Data!U$2:U$218,0)) -> East Asia & Pacific | E24: =INDEX(Clean_Data!T$2:T$218,MATCH(F24,Clean_Data!U$2:U$218,0)) -> 68.3 | F24: =LARGE(Clean_Data!U$2:U$218,B24) -> 68.300019
